Workbook

Sheet May 
A1: Department | B1: Team Lead | C1: Full Name | D1: State | E1: Tardiness | F1: Absences | G1: Lost Hours | H1: Target | I1: Completed | J1: Attendance | K1: Late | L1: Absent | M1: VL | N1: SL | O1: LWOP | P1: SPL | Q1: Emergency | R1: Infraction Issued | S1: Offense | T1: Coaching Log # | U1: Date Issued | V1: Infraction
A2: Billing | B2: Kate Constantino | C2: Alexandra Ortiz | D2: KY | E2: 231 | F2: 1620 | G2: 1620 | H2: 10800 | I2: 9180 | J2: 0.85 | K2: 5 | N2: 3
A3: Rejection | B3: Vladimir Patio | C3: Alyssa DeGuzman | D3: KY | E3: 262 | F3: 540 | G3: 802 | H3: 11880 | I3: 11078 | J3: 0.93249158 | K3: 9 | L3: 1 | O3: 2
A4: Rejection | B4: Vladimir Patio | C4: Analyn Caniedo | D4: IL | E4: 374 | F4: 540 | G4: 914 | H4: 11880 | I4: 10966 | J4: 0.92306397 | K4: 9 | L4: 1
A5: Billing | B5: Louis Cantillion | C5: Analyn Diaz | D5: NJ | E5: 32 | F5: 2160 | G5: 2192 | H5: 11880 | I5: 9688 | J5: 0.81548822 | K5: 3 | L5: 4
A6: Rejection | B6: Edmark Bania | C6: Andrea Fonacier | D6: KY/IL | E6: 31 | G6: 31 | H6: 11880 | I6: 11849 | J6: 0.99739057 | K6: 7
A7: Intake | B7: Kiana Brown | C7: Angelica Bautista | D7: Multi | E7: 533 | F7: 540 | G7: 1073 | H7: 11880 | I7: 10807 | J7: 0.90968013 | K7: 4 | L7: 1
A8: Billing | B8: Louis Cantillion | C8: Angelo Agron | D8: NJ | E8: 27 | F8: 2160 | G8: 2187 | H8: 11340 | I8: 9153 | J8: 0.80714286 | K8: 7 | L8: 4 | O8: 1
A9: Billing | B9: Kate Constantino | C9: Anthea Ann Lumen | D9: KY | E9: 41 | G9: 41 | H9: 11340 | I9: 11299 | J9: 0.99638448 | K9: 4 | O9: 1
A10: Billing | B10: Kate Constantino | C10: Anthony Valdez | D10: KY | E10: 0 | F10: 540 | G10: 540 | H10: 10260 | I10: 9720 | J10: 0.94736842 | M10: 3 | N10: 1
A11: Intake | B11: Kiana Brown | C11: Ar Jean Tudtud | D11: Multi | E11: 8 | G11: 8 | H11: 11880 | I11: 11872 | J11: 0.9993266 | K11: 2
A12: Rejection | B12: Vladimir Patio | C12: Arah Blancia | D12: IL | F12: 1620 | G12: 1620 | H12: 11880 | I12: 10260 | J12: 0.86363636 | L12: 3
A13: Rejection | B13: Edmark Bania | C13: Audrey De Leon | D13: NJ | F13: 1080 | G13: 1080 | H13: 10800 | I13: 9720 | J13: 0.9 | L13: 1 | M13: 2 | N13: 1
A14: Rejection | B14: Vladimir Patio | C14: Avril Rie Son | D14: NJ | E14: 44 | F14: 540 | G14: 584 | H14: 11880 | I14: 11296 | J14: 0.95084175 | K14: 5 | L14: 1
A15: Rejection | B15: Vladimir Patio | C15: Bea Mercado | D15: NJ | F15: 1080 | G15: 1080 | H15: 11340 | I15: 10260 | J15: 0.9047619 | L15: 2 | O15: 1
A16: Rejection | B16: Vladimir Patio | C16: Charlene Valdez | D16: MA/NY/NJ (KY/IL) | E16: 46 | F16: 540 | G16: 586 | H16: 11880 | I16: 11294 | J16: 0.9506734 | K16: 3 | N16: 1
A17: Rejection | B17: Vladimir Patio | C17: Charyselle Cadelina | D17: KY | E17: 29 | F17: 1080 | G17: 1109 | H17: 11880 | I17: 10771 | J17: 0.90664983 | K17: 3 | N17: 2
A18: Intake | B18: Kiana Brown | C18: Collen Silapan | D18: Multi | E18: 48 | G18: 48 | H18: 11340 | I18: 11292 | J18: 0.9957672 | K18: 3
A19: Rejection | B19: Vladimir Patio | C19: Danielle Generao | D19: KY | E19: 194 | F19: 1080 | G19: 1274 | H19: 10800 | I19: 9526 | J19: 0.88203704 | K19: 7 | L19: 2 | O19: 2
A20: Rejection | B20: Rhoda De Jesus | C20: Edmark Bania | D20: Multi | F20: 540 | G20: 540 | H20: 10800 | I20: 10260 | J20: 0.95 | M20: 2 | N20: 1
A21: Billing | B21: Rhoda De Jesus | C21: Eldrick Loreno | D21: NY | E21: 419 | F21: 1080 | G21: 1499 | H21: 10260 | I21: 8761 | J21: 0.85389864 | K21: 3 | M21: 3 | N21: 2
A22: Mpen | B22: Hans Ruan | C22: Erika Ramos | D22: Rebill | E22: 16 | F22: 0 | G22: 16 | H22: 11880 | I22: 11864 | J22: 0.9986532 | K22: 1
A23: Billing | B23: Jason Cruz | C23: Ethel Gregorio | D23: MA | E23: 237 | F23: 1620 | G23: 1857 | H23: 11880 | I23: 10023 | J23: 0.84368687 | K23: 16 | L23: 3
A24: Billing | B24: Jason Cruz | C24: Eunice Bargo | D24: MA | E24: 77 | F24: 540 | G24: 617 | H24: 11880 | I24: 11263 | J24: 0.94806397 | K24: 8 | N24: 1
A25: Rejection | B25: Edmark Bania | C25: Eunice Padadnan | D25: NY | E25: 1 | G25: 1 | H25: 11880 | I25: 11879 | J25: 0.99991582 | K25: 1
A26: Billing | B26: Noemi Landerito | C26: Femie DC Domenden | D26: IL | E26: 39 | G26: 39 | H26: 11880 | I26: 11841 | J26: 0.99671717 | K26: 3 | O26: 1
A27: Rejection | B27: Vladimir Patio | C27: Francis Alba | D27: Multi | E27: 42 | F27: 540 | G27: 582 | H27: 10800 | I27: 10218 | J27: 0.94611111 | K27: 2 | M27: 2 | N27: 1
A28: Billing | B28: Noemi Landerito | C28: Francis Narboneta | D28: IL | E28: 317 | F28: 2700 | G28: 3017 | H28: 11340 | I28: 8323 | J28: 0.73395062 | K28: 3 | L28: 5 | M28: 1 | O28: 1
A29: Billing | B29: Jason Cruz | C29: Gladys Astilla | D29: MA | E29: 26 | G29: 26 | H29: 11880 | I29: 11854 | J29: 0.99781145 | K29: 3
A30: Rejection | B30: Vladimir Patio | C30: Glessie DeJesus | D30: KY | F30: 1620 | G30: 1620 | H30: 11880 | I30: 10260 | J30: 0.86363636 | L30: 3
A31: Billing | B31: Noemi Landerito | C31: Glory Nabayra | D31: IL | E31: 23 | F31: 540 | G31: 563 | H31: 11880 | I31: 11317 | J31: 0.95260943 | K31: 3 | L31: 1
A32: Rejection | B32: Vladimir Patio | C32: Hanna Arceo | D32: KY | E32: 71 | F32: 1080 | G32: 1151 | H32: 11880 | I32: 10729 | J32: 0.90311448 | K32: 8 | N32: 2
A33: Mpen | B33: Rhoda De Jesus | C33: Hans Ruan | D33: Multi | E33: 9 | F33: 540 | G33: 549 | H33: 11340 | I33: 10791 | J33: 0.9515873 | K33: 1 | M33: 1 | N33: 1
A34: Intake | B34: Kiana Brown | C34: Hazelyn Rodrigo | D34: Multi | E34: 300 | G34: 300 | H34: 11340 | I34: 11040 | J34: 0.97354497 | K34: 6
A35: Rejection | B35: Vladimir Patio | C35: Iris Dahnielle Andalleon | D35: Multi | E35: 9 | F35: 0 | G35: 9 | H35: 11340 | I35: 11331 | J35: 0.99920635 | K35: 2 | M35: 1
A36: Intake | B36: Kiana Brown | C36: Isabela Arellano | D36: Multi | E36: 303 | G36: 303 | H36: 11340 | I36: 11037 | J36: 0.97328042 | K36: 6 | O36: 1
A37: Billing | B37: Noemi Landerito | C37: Iverson Libranda | D37: IL | E37: 151 | F37: 540 | G37: 691 | H37: 11880 | I37: 11189 | J37: 0.94183502 | K37: 5
A38: Billing | B38: Rhoda De Jesus | C38: Jason Cruz | D38: MA | E38: 15 | F38: 540 | G38: 555 | H38: 10260 | I38: 9705 | J38: 0.94590643 | K38: 1 | M38: 3 | N38: 1
A39: Rejection | B39: Vladimir Patio | C39: Jean Tan | D39: NY NJ | E39: 1 | F39: 540 | G39: 541 | H39: 11880 | I39: 11339 | J39: 0.95446128 | K39: 1 | N39: 1
A40: Rejection | B40: Edmark Bania | C40: Jeannie Bajaro | D40: Multi | F40: 540 | G40: 540 | H40: 11340 | I40: 10800 | J40: 0.95238095 | M40: 1 | N40: 1
...

Sheet JWeek 1
A1: Department | B1: Full Name | C1: State | D1: SUNDAY | E1: MONDAY | F1: TUESDAY | G1: WEDNESDAY | H1: THURSDAY | I1: FRIDAY | J1: SATURDAY | K1: Tardiness | L1: Absences | M1: Lost Hours | N1: Target | O1: Completed | P1: Attendance | Q1: VL | R1: LWOP | T1: Row Labels | U1: Sum of Tardiness | V1: Sum of Absences | W1: Sum of Target | X1: Sum of Completed
A2: Billing | B2: Alexandra Ortiz | C2: KY | D2: RD | E2: 450 | F2: 5 | G2: P | H2: 19 | I2: P | J2: RD | K2: =SUM(F2:I2) -> 24 | L2: =SUMIF(D2:J2,"450") -> 450 | M2: =SUM(K2:L2) -> 474 | N2: =450*5 -> 2250 | O2: =N2-M2 -> 1776 | P2: =O2/N2*100% -> 0.78933333 | T2: ALF | U2: 0 | V2: 0 | W2: 2250 | X2: 2250
A3: Rejection | B3: Alyssa DeGuzman | C3: KY | D3: P | E3: 17 | F3: RD | G3: RD | H3: 4 | I3: P | J3: P | K3: =SUM(D3:J3) -> 21 | L3: =SUMIF(D3:J3,"450") -> 0 | M3: =SUM(K3:L3) -> 21 | N3: =450*5 -> 2250 | O3: =N3-M3 -> 2229 | P3: =O3/N3*100% -> 0.99066667 | T3: Billing | U3: 914 | V3: 1350 | W3: 96300 | X3: 94036
A4: Rejection | B4: Analyn Caniedo | C4: IL | D4: 25 | E4: 4 | F4: RD | G4: RD | H4: P | I4: P | J4: P | K4: =SUM(D4:J4) -> 29 | L4: =SUMIF(D4:J4,"450") -> 0 | M4: =SUM(K4:L4) -> 29 | N4: =450*5 -> 2250 | O4: =N4-M4 -> 2221 | P4: =O4/N4*100% -> 0.98711111 | T4: Intake | U4: 639 | V4: 0 | W4: 22500 | X4: 21861
A5: Billing | B5: Analyn Diaz | C5: NJ | D5: RD | E5: 9 | F5: 4 | G5: P | H5: 8 | I5: 9 | J5: RD | K5: =SUM(E5:I5) -> 30 | L5: =SUMIF(D5:J5,"450") -> 0 | M5: =SUM(K5:L5) -> 30 | N5: =450*5 -> 2250 | O5: =N5-M5 -> 2220 | P5: =O5/N5*100% -> 0.98666667 | T5: Mpen | U5: 0 | V5: 450 | W5: 9000 | X5: 8550
A6: Rejection | B6: Andrea Fonacier | C6: KY/IL | D6: RD | E6: 450 | F6: P | G6: 13 | H6: P | I6: P | J6: RD | K6: =G6 -> 13 | L6: =SUMIF(D6:J6,"450") -> 450 | M6: =SUM(K6:L6) -> 463 | N6: =450*5 -> 2250 | O6: =N6-M6 -> 1787 | P6: =O6/N6*100% -> 0.79422222 | T6: Rebill | U6: 60 | V6: 0 | W6: 4500 | X6: 4440
A7: Intake | B7: Angelica Bautista | C7: Multi | D7: P | E7: 1 | F7: 1 | G7: P | H7: P | I7: RD | J7: RD | K7: =SUM(D7:J7) -> 2 | L7: =SUMIF(D7:J7,"450") -> 0 | M7: =SUM(K7:L7) -> 2 | N7: =450*5 -> 2250 | O7: =N7-M7 -> 2248 | P7: =O7/N7*100% -> 0.99911111 | T7: Rejection | U7: 749 | V7: 1350 | W7: 80550 | X7: 78451
A8: Billing | B8: Angelo Agron | C8: NJ | D8: P | E8: P | F8: P | G8: 2 | H8: P | I8: P | J8: RD | K8: =SUM(E8:I8) -> 2 | L8: =SUMIF(D8:J8,"450") -> 0 | M8: =SUM(K8:L8) -> 2 | N8: =450*5 -> 2250 | O8: =N8-M8 -> 2248 | P8: =O8/N8*100% -> 0.99911111 | T8: Grand Total | U8: 2362 | V8: 3150 | W8: 215100 | X8: 209588
A9: Billing | B9: Anthea Ann Lumen | C9: KY | D9: P | E9: 5 | F9: P | G9: P | H9: 7 | I9: 17 | J9: RD | K9: =SUM(D9:I9) -> 29 | L9: =SUMIF(D9:J9,"450") -> 0 | M9: =SUM(K9:L9) -> 29 | N9: =450*5 -> 2250 | O9: =N9-M9 -> 2221 | P9: =O9/N9*100% -> 0.98711111
A10: Billing | B10: Anthony Valdez | C10: KY | D10: P | E10: P | F10: P | G10: P | H10: P | I10: P | J10: RD | K10: =SUM(D10:I10) -> 0 | L10: =SUMIF(D10:J10,"450") -> 0 | M10: =SUM(K10:L10) -> 0 | N10: =450*5 -> 2250 | O10: =N10-M10 -> 2250 | P10: =O10/N10*100% -> 1
A11: Intake | B11: Ar Jean Tudtud | C11: Multi | D11: RD | E11: RD | F11: P | G11: P | H11: P | I11: P | J11: P | K11: =SUM(D11:I11) -> 0 | L11: =SUMIF(D11:J11,"450") -> 0 | M11: =SUM(K11:L11) -> 0 | N11: =450*5 -> 2250 | O11: =N11-M11 -> 2250 | P11: =O11/N11*100% -> 1 | T11: Row Labels | U11: Sum of Completed
A12: Rejection | B12: Arah Blancia | C12: IL | D12: P | E12: P | F12: 6 | G12: RD | H12: RD | I12: P | J12: P | K12: =SUM(D12:J12) -> 6 | L12: =SUMIF(D12:J12,"450") -> 0 | M12: =SUM(K12:L12) -> 6 | N12: =450*5 -> 2250 | O12: =N12-M12 -> 2244 | P12: =O12/N12*100% -> 0.99733333 | T12: Rejection | U12: 78451
A13: Rejection | B13: Avril Rie Son | C13: NJ | D13: RD | E13: 450 | F13: P | G13: P | H13: P | I13: P | J13: RD | L13: =SUMIF(D13:J13,"450") -> 450 | M13: =SUM(K13:L13) -> 450 | N13: =450*5 -> 2250 | O13: =N13-M13 -> 1800 | P13: =O13/N13*100% -> 0.8 | T13: Alyssa DeGuzman | U13: 2229
A14: Rejection | B14: Bea Mercado | C14: NJ | D14: RD | E14: P | F14: P | G14: P | H14: P | I14: P | J14: RD | K14: =SUM(D14:J14) -> 0 | L14: =SUMIF(D14:J14,"450") -> 0 | M14: =SUM(K14:L14) -> 0 | N14: =450*5 -> 2250 | O14: =N14-M14 -> 2250 | P14: =O14/N14*100% -> 1 | R14: 1 | T14: Analyn Caniedo | U14: 2221
A15: Rejection | B15: Charlene Valdez | C15: MA/NY/NJ (KY/IL) | D15: RD | E15: P | F15: P | G15: 3 | H15: P | I15: P | J15: RD | K15: =SUM(D15:J15) -> 3 | L15: =SUMIF(D15:J15,"450") -> 0 | M15: =SUM(K15:L15) -> 3 | N15: =450*5 -> 2250 | O15: =N15-M15 -> 2247 | P15: =O15/N15*100% -> 0.99866667 | T15: Andrea Fonacier | U15: 1787
A16: Rejection | B16: Charyselle Cadelina | C16: KY | D16: RD | E16: 5 | F16: P | G16: P | H16: P | I16: P | J16: RD | K16: =SUM(D16:J16) -> 5 | L16: =SUMIF(D16:J16,"450") -> 0 | M16: =SUM(K16:L16) -> 5 | N16: =450*5 -> 2250 | O16: =N16-M16 -> 2245 | P16: =O16/N16*100% -> 0.99777778 | T16: Arah Blancia | U16: 2244
A17: Intake | B17: Collen Silapan | C17: Multi | D17: 5 | E17: P | F17: P | G17: P | H17: P | I17: RD | J17: RD | K17: =SUM(D17:J17) -> 5 | L17: =SUMIF(D17:J17,"450") -> 0 | M17: =SUM(K17:L17) -> 5 | N17: =450*5 -> 2250 | O17: =N17-M17 -> 2245 | P17: =O17/N17*100% -> 0.99777778 | T17: Avril Rie Son | U17: 1800
A18: Rejection | B18: Danielle Generao | C18: KY | D18: RD | E18: P | F18: P | G18: 8 | H18: 6 | I18: P | J18: RD | K18: =SUM(D18:J18) -> 14 | L18: =SUMIF(D18:J18,"450") -> 0 | M18: =SUM(K18:L18) -> 14 | N18: =450*5 -> 2250 | O18: =N18-M18 -> 2236 | P18: =O18/N18*100% -> 0.99377778 | T18: Bea Mercado | U18: 2250
A19: Rejection | B19: Edmark Bania | C19: Multi | D19: RD | E19: P | F19: P | G19: RD | H19: RD | I19: P | J19: P | K19: =SUM(D19:J19) -> 0 | L19: =SUMIF(D19:J19,"450") -> 0 | M19: =SUM(K19:L19) -> 0 | N19: =450*4 -> 1800 | O19: =N19-M19 -> 1800 | P19: =O19/N19*100% -> 1 | Q19: 2 | T19: Charlene Valdez | U19: 2247
A20: Billing | B20: Eldrick Loreno | C20: NY | D20: P | E20: P | F20: P | G20: P | H20: P | I20: P | J20: RD | K20: =SUM(D20:I20) -> 0 | L20: =SUMIF(D20:J20,"450") -> 0 | M20: =SUM(K20:L20) -> 0 | N20: =450*5 -> 2250 | O20: =N20-M20 -> 2250 | P20: =O20/N20*100% -> 1 | Q20: 1 | T20: Charyselle Cadelina | U20: 2245
A21: Rebill | B21: Erika Ramos | C21: Multi | D21: RD | E21: 12 | F21: P | G21: P | H21: P | I21: P | J21: RD | K21: =SUM(E21:I21) -> 12 | L21: =SUMIF(D21:J21,"450") -> 0 | M21: =SUM(K21:L21) -> 12 | N21: =450*5 -> 2250 | O21: =N21-M21 -> 2238 | P21: =O21/N21*100% -> 0.99466667 | T21: Danielle Generao | U21: 2236
A22: Billing | B22: Ethel Gregorio | C22: MA | D22: P | E22: 26 | F22: 13 | G22: 143 | H22: 11 | I22: P | J22: RD | K22: =SUM(D22:I22) -> 193 | L22: =SUMIF(D22:J22,"450") -> 0 | M22: =SUM(K22:L22) -> 193 | N22: =450*5 -> 2250 | O22: =N22-M22 -> 2057 | P22: =O22/N22*100% -> 0.91422222 | T22: Edmark Bania | U22: 1800
A23: Billing | B23: Eunice Bargo | C23: MA | D23: RD | E23: P | F23: P | G23: P | H23: P | I23: P | J23: RD | K23: =SUM(D23:I23) -> 0 | L23: =SUMIF(D23:J23,"450") -> 0 | M23: =SUM(K23:L23) -> 0 | N23: =450*5 -> 2250 | O23: =N23-M23 -> 2250 | P23: =O23/N23*100% -> 1 | T23: Eunice Padadnan | U23: 2250
A24: Rejection | B24: Eunice Padadnan | C24: NY | D24: RD | E24: P | F24: P | G24: P | H24: P | I24: P | J24: RD | K24: =SUM(D24:J24) -> 0 | L24: =SUMIF(D24:J24,"450") -> 0 | M24: =SUM(K24:L24) -> 0 | N24: =450*5 -> 2250 | O24: =N24-M24 -> 2250 | P24: =O24/N24*100% -> 1 | T24: Francis Alba | U24: 2216
A25: Billing | B25: Femie DC Domenden | C25: IL | D25: P | E25: P | F25: P | G25: P | H25: P | I25: P | J25: RD | K25: =SUM(D25:J25) -> 0 | L25: =SUMIF(D25:J25,"450") -> 0 | M25: =SUM(K25:L25) -> 0 | N25: =450*5 -> 2250 | O25: =N25-M25 -> 2250 | P25: =O25/N25*100% -> 1 | T25: Glessie DeJesus | U25: 2250
A26: Rejection | B26: Francis Alba | C26: Multi | D26: RD | E26: P | F26: P | G26: P | H26: 34 | I26: P | J26: RD | K26: =SUM(D26:J26) -> 34 | L26: =SUMIF(D26:J26,"450") -> 0 | M26: =SUM(K26:L26) -> 34 | N26: =450*5 -> 2250 | O26: =N26-M26 -> 2216 | P26: =O26/N26*100% -> 0.98488889 | Q26: 2 | T26: Hanna Arceo | U26: 2231
A27: Billing | B27: Francis Narboneta | C27: IL | D27: RD | E27: 450 | F27: 8 | G27: P | H27: 3 | I27: P | J27: RD | K27: =F27+H27 -> 11 | L27: =SUMIF(D27:J27,"450") -> 450 | M27: =SUM(K27:L27) -> 461 | N27: =450*5 -> 2250 | O27: =N27-M27 -> 1789 | P27: =O27/N27*100% -> 0.79511111 | T27: Iris Dahnielle Andalleon | U27: 2247
A28: Billing | B28: Gladys Astilla | C28: MA | D28: P | E28: P | F28: P | G28: 9 | H28: P | I28: P | J28: RD | K28: =SUM(D28:I28) -> 9 | L28: =SUMIF(D28:J28,"450") -> 0 | M28: =SUM(K28:L28) -> 9 | N28: =450*5 -> 2250 | O28: =N28-M28 -> 2241 | P28: =O28/N28*100% -> 0.996 | T28: Jean Tan | U28: 2250
A29: Rejection | B29: Glessie DeJesus | C29: KY | D29: RD | E29: P | F29: P | G29: P | H29: P | I29: P | J29: RD | K29: =SUM(D29:J29) -> 0 | L29: =SUMIF(D29:J29,"450") -> 0 | M29: =SUM(K29:L29) -> 0 | N29: =450*5 -> 2250 | O29: =N29-M29 -> 2250 | P29: =O29/N29*100% -> 1 | T29: Jeannie Bajaro | U29: 2250
A30: Billing | B30: Glory Nabayra | C30: IL | D30: P | E30: 4 | F30: P | G30: P | H30: 5 | I30: P | J30: RD | K30: =SUM(D30:J30) -> 9 | L30: =SUMIF(D30:J30,"450") -> 0 | M30: =SUM(K30:L30) -> 9 | N30: =450*5 -> 2250 | O30: =N30-M30 -> 2241 | P30: =O30/N30*100% -> 0.996 | T30: Jericho Crame | U30: 2250
A31: Rejection | B31: Hanna Arceo | C31: KY | D31: RD | E31: 6 | F31: P | G31: P | H31: P | I31: 13 | J31: RD | K31: =SUM(D31:J31) -> 19 | L31: =SUMIF(D31:J31,"450") -> 0 | M31: =SUM(K31:L31) -> 19 | N31: =450*5 -> 2250 | O31: =N31-M31 -> 2231 | P31: =O31/N31*100% -> 0.99155556 | T31: Jizelle Delos Reyes | U31: 2250
A32: Mpen | B32: Hans Ruan | C32: Multi | D32: RD | E32: P | F32: P | G32: P | H32: P | I32: P | J32: RD | K32: =SUM(E32:I32) -> 0 | L32: =SUMIF(D32:J32,"450") -> 0 | M32: =SUM(K32:L32) -> 0 | N32: =450*5 -> 2250 | O32: =N32-M32 -> 2250 | P32: =O32/N32*100% -> 1 | T32: Joanna Cabrera | U32: 2250
A33: Intake | B33: Hazelyn Rodrigo | C33: Multi | D33: 7 | E33: 5 | F33: RD | G33: RD | H33: P | I33: 13 | J33: P | K33: =SUM(D33:J33) -> 25 | L33: =SUMIF(D33:J33,"450") -> 0 | M33: =SUM(K33:L33) -> 25 | N33: =450*5 -> 2250 | O33: =N33-M33 -> 2225 | P33: =O33/N33*100% -> 0.98888889 | T33: Jonathan Marquez | U33: 2244
A34: Rejection | B34: Iris Dahnielle Andalleon | C34: Multi | D34: P | E34: P | F34: 3 | G34: RD | H34: RD | I34: P | J34: P | K34: =SUM(D34:J34) -> 3 | L34: =SUMIF(D34:J34,"450") -> 0 | M34: =SUM(K34:L34) -> 3 | N34: =450*5 -> 2250 | O34: =N34-M34 -> 2247 | P34: =O34/N34*100% -> 0.99866667 | Q34: 1 | T34: Jullyca Oblefias | U34: 2250
A35: Intake | B35: Isabela Arellano | C35: Multi | D35: P | E35: P | F35: P | G35: P | H35: 7 | I35: RD | J35: RD | K35: =SUM(D35:J35) -> 7 | L35: =SUMIF(D35:J35,"450") -> 0 | M35: =SUM(K35:L35) -> 7 | N35: =450*5 -> 2250 | O35: =N35-M35 -> 2243 | P35: =O35/N35*100% -> 0.99688889 | T35: Karlos De Leon | U35: 2250
A36: Billing | B36: Iverson Libranda | C36: IL | D36: RD | E36: LWOP | F36: P | G36: 28 | H36: P | I36: P | J36: RD | K36: =SUM(D36:J36) -> 28 | L36: =SUMIF(D36:J36,"450") -> 0 | M36: =SUM(K36:L36) -> 28 | N36: =450*5 -> 2250 | O36: =N36-M36 -> 2222 | P36: =O36/N36*100% -> 0.98755556 | T36: Kaxyleh Masilongan | U36: 2243
A37: Billing | B37: Jason Cruz | C37: MA | D37: P | E37: P | F37: P | G37: P | H37: P | I37: P | J37: RD | K37: =SUM(D37:I37) -> 0 | L37: =SUMIF(D37:J37,"450") -> 0 | M37: =SUM(K37:L37) -> 0 | N37: =450*5 -> 2250 | O37: =N37-M37 -> 2250 | P37: =O37/N37*100% -> 1 | T37: Kizzy Serrano | U37: 2247
A38: Rejection | B38: Jean Tan | C38: NY NJ | D38: RD | E38: P | F38: P | G38: P | H38: P | I38: P | J38: RD | K38: =SUM(D38:J38) -> 0 | L38: =SUMIF(D38:J38,"450") -> 0 | M38: =SUM(K38:L38) -> 0 | N38: =450*5 -> 2250 | O38: =N38-M38 -> 2250 | P38: =O38/N38*100% -> 1 | T38: Margie Theres A Magluyan | U38: 2250
A39: Rejection | B39: Jeannie Bajaro | C39: Multi | D39: P | E39: P | F39: P | G39: RD | H39: RD | I39: P | J39: P | K39: =SUM(D39:J39) -> 0 | L39: =SUMIF(D39:J39,"450") -> 0 | M39: =SUM(K39:L39) -> 0 | N39: =450*5 -> 2250 | O39: =N39-M39 -> 2250 | P39: =O39/N39*100% -> 1 | T39: Mary Dela Cruz | U39: 2250
A40: Rejection | B40: Jericho Crame | C40: NJ | D40: RD | E40: P | F40: P | G40: P | H40: P | I40: P | J40: RD | K40: =SUM(D40:J40) -> 0 | L40: =SUMIF(D40:J40,"450") -> 0 | M40: =SUM(K40:L40) -> 0 | N40: =450*5 -> 2250 | O40: =N40-M40 -> 2250 | P40: =O40/N40*100% -> 1 | T40: Mary Kilario | U40: 2250
...

Sheet May Absenteeism
A3: Row Labels | B3: Sum of Target | C3: Sum of Tardiness | D3: Sum of Absences | I3: Row Labels | J3: Sum of Target | K3: Sum of Tardiness | L3: Sum of Absences
A4: Billing | B4: 480600 | C4: 4451 | D4: 35640 | I4: Billing | J4: 427140 | K4: 3915 | L4: 31320
A5: Intake | B5: 118260 | C5: 1304 | D5: 4320 | I5: Eldrick Loreno | J5: 45900 | K5: 397 | L5: 2700
A6: Mpen | B6: 78300 | C6: 105 | D6: 3780 | I6: Jason Cruz | J6: 103140 | K6: 521 | L6: 8640
A7: Rejection | B7: 443880 | C7: 2903 | D7: 31320 | I7: Kate Constantino | J7: 78300 | K7: 820 | L7: 5940
A8: (blank) | I8: Louis Cantillion | J8: 93420 | K8: 1092 | L8: 9180
A9: Grand Total | B9: 1121040 | C9: 8763 | D9: 75060 | I9: Noemi Landerito | J9: 106380 | K9: 1085 | L9: 4860
I10: Intake | J10: 105840 | K10: 1304 | L10: 4320
A11: Row Labels | B11: Sum of Target | C11: Sum of Tardiness | D11: Average | E11: Sum of Absences | F11: Average | I11: Kiana Brown | J11: 105840 | K11: 1304 | L11: 4320
A12: Billing | B12: 427140 | C12: 3915 | D12: =C12/B12 -> 0.0091656131 | E12: 31320 | F12: =E12/B12 -> 0.073324905 | I12: Mpen | J12: 66960 | K12: 96 | L12: 3240
A13: Intake | B13: 105840 | C13: 1304 | D13: =C13/B13 -> 0.012320484 | E13: 3780 | F13: =E13/B13 -> 0.035714286 | I13: Hans Ruan | J13: 66960 | K13: 96 | L13: 3240
A14: Mpen | B14: 66960 | C14: 96 | D14: =C14/B14 -> 0.0014336918 | E14: 3240 | F14: =E14/B14 -> 0.048387097 | I14: Rejection | J14: 421200 | K14: 2896 | L14: 30780
A15: Rejection | B15: 421200 | C15: 2896 | D15: =C15/B15 -> 0.0068755935 | E15: 30780 | F15: =E15/B15 -> 0.073076923 | I15: Edmark Bania | J15: 199260 | K15: 905 | L15: 14040
A16: Grand Total | B16: 1021140 | C16: 8211 | D16: =C16/B16 -> 0.008041013 | E16: 69120 | F16: =E16/B16 -> 0.067689053 | I16: Vladimir Patio | J16: 221940 | K16: 1991 | L16: 16740
I17: Grand Total | J17: 1021140 | K17: 8211 | L17: 69660
A20: Row Labels | B20: Sum of SL | C20: Sum of Absent | D20: Sum of VL | E20: Sum of LWOP | I20: Department/Team Lead | J20: Total Sick Leave | K20: Total Other/Absences | L20: Total Vacation Leave | M20: Total Leave without Pay
A21: Billing | B21: 25 | C21: 31 | D21: 13 | E21: 12 | I21: Billing | J21: 25 | K21: 31 | L21: 13 | M21: 12
A22: Eldrick Loreno | B22: 5 | D22: 2 | E22: 1 | I22: Eldrick Loreno | J22: 5 | L22: 2 | M22: 1
A23: Jason Cruz | B23: 10 | C23: 6 | D23: 5 | E23: 2 | I23: Jason Cruz | J23: 10 | K23: 6 | L23: 5 | M23: 2
A24: Kate Constantino | B24: 4 | C24: 7 | D24: 3 | E24: 4 | I24: Kate Constantino | J24: 4 | K24: 7 | L24: 3 | M24: 4
A25: Louis Cantillion | B25: 5 | C25: 11 | E25: 3 | I25: Louis Cantillion | J25: 5 | K25: 11 | M25: 3
A26: Noemi Landerito | B26: 1 | C26: 7 | D26: 3 | E26: 2 | I26: Noemi Landerito | J26: 1 | K26: 7 | L26: 3 | M26: 2
A27: Intake | B27: 6 | C27: 2 | E27: 2 | I27: Intake | J27: 6 | K27: 2 | M27: 2
A28: Kiana Brown | B28: 6 | C28: 2 | E28: 2 | I28: Kiana Brown | J28: 6 | K28: 2 | M28: 2
A29: Mpen | B29: 4 | C29: 2 | D29: 5 | E29: 3 | I29: Medicaid Pending | J29: 4 | K29: 2 | L29: 5 | M29: 3
A30: Hans Ruan | B30: 4 | C30: 2 | D30: 5 | E30: 3 | I30: Hans Ruan | J30: 4 | K30: 2 | L30: 5 | M30: 3
A31: Rejection | B31: 37 | C31: 20 | D31: 7 | E31: 5 | I31: Rejection | J31: 37 | K31: 20 | L31: 7 | M31: 5
A32: Edmark Bania | B32: 25 | C32: 1 | D32: 3 | I32: Edmark Bania | J32: 25 | K32: 1 | L32: 3
A33: Vladimir Patio | B33: 12 | C33: 19 | D33: 4 | E33: 5 | I33: Vladimir Patio | J33: 12 | K33: 19 | L33: 4 | M33: 5
A34: Grand Total | B34: 72 | C34: 55 | D34: 25 | E34: 22 | I34: Grand Total | J34: 72 | K34: 55 | L34: 25 | M34: 22

Sheet May Report
J2: Row Labels | K2: Average of Attendance | M2: Row Labels | N2: Average of Attendance | P2: Row Labels | Q2: Average of Attendance
A3: Row Labels | B3: Average of Attendance | J3: Billing | K3: 0.91663602 | M3: Intake | N3: 0.95240924 | P3: Rejection | Q3: 0.92307878
A4: Billing | B4: 0.91663602 | J4: Eldrick Loreno | K4: 0.93316679 | M4: Kiana Brown | N4: 0.94712137 | P4: Edmark Bania | Q4: 0.92495614
A5: Intake | B5: 0.95240924 | J5: Mark Bienes | K5: 0.97878788 | M5: Angelica Bautista | N5: 0.90968013 | P5: Andrea Fonacier | Q5: 0.99739057
A6: Mpen | B6: 0.94771587 | J6: Syra Jade Yaranon | K6: 0.89983165 | M6: Ar Jean Tudtud | N6: 0.9993266 | P6: Audrey De Leon | Q6: 0.9
A7: Rejection | B7: 0.92307878 | J7: Vianka Ylaine Ortiz | K7: 0.99981481 | M7: Collen Silapan | N7: 0.9957672 | P7: Eunice Padadnan | Q7: 0.99991582
A8: Grand Total | B8: 0.92509083 | J8: Xenrel Mae O Dacubar | K8: 0.8542328 | M8: Hazelyn Rodrigo | N8: 0.97354497 | P8: Jeannie Bajaro | Q8: 0.95238095
J9: Jason Cruz | K9: 0.91008312 | M9: Isabela Arellano | N9: 0.97328042 | P9: Jericho Crame | Q9: 1
J10: Ethel Gregorio | K10: 0.84368687 | M10: Josea Aseron | N10: 0.99774557 | P10: Jester Limpin | Q10: 0.85488215
A11: Average of Attendance | B11: Column Labels | J11: Eunice Bargo | K11: 0.94806397 | M11: Katrina Go | N11: 0.95454545 | P11: Jonathan Marquez | Q11: 0.99048822
A12: Row Labels | B12: Eldrick Loreno | C12: Jason Cruz | D12: Kate Constantino | E12: Louis Cantillion | F12: Noemi Landerito | G12: Grand Total | J12: Gladys Astilla | K12: 0.99781145 | M12: Nerissa Ong | N12: 0.72382155 | P12: Jullyca Oblefias | Q12: 1
A13: Billing | B13: 0.93316679 | C13: 0.91008312 | D13: 0.91690078 | E13: 0.8902417 | F13: 0.943054 | G13: 0.91759839 | J13: Jimwell Osiang | K13: 0.99461279 | M13: Remaden Bautista | N13: 0.99638047 | P13: Karlos De Leon | Q13: 0.5
A14: Grand Total | B14: 0.93316679 | C14: 0.91008312 | D14: 0.91690078 | E14: 0.8902417 | F14: 0.943054 | G14: 0.91759839 | J14: Julieann Manasan | K14: 0.80952381 | M14: Rhoda De Jesus | N14: 1 | P14: Kaxyleh Masilongan | Q14: 0.99671717
J15: Kyzen Hayagan | K15: 0.90816498 | M15: Kiana Brown | N15: 1 | P15: Kizzy Serrano | Q15: 0.90345118
A16: Average of Attendance | B16: Column Labels | J16: Lea Alagadmo | K16: 0.93816872 | M16: Grand Total | N16: 0.95240924 | P16: Margie Theres A Magluyan | Q16: 0.96186869
A17: Row Labels | B17: Hans Ruan | C17: Kiana Brown | D17: Grand Total | J17: Rafunzel M Manuel | K17: 0.95117845 | P17: Mary Dela Cruz | Q17: 1
A18: Intake | C18: 0.94712137 | D18: 0.94712137 | J18: Rosalinda Pantua | K18: 0.79953704 | M18: Row Labels | N18: Average of Attendance | P18: Rhona Sanejo | Q18: 1
A19: Mpen | B19: 0.94707063 | D19: 0.94707063 | J19: Kate Constantino | K19: 0.91690078 | M19: Mpen | N19: 0.94771587 | P19: Rubyneil Abejero | Q19: 0.9983165
A20: Grand Total | B20: 0.94707063 | C20: 0.94712137 | D20: 0.94710108 | J20: Alexandra Ortiz | K20: 0.85 | M20: Hans Ruan | N20: 0.94707063 | P20: Ruth Dela Cruz | Q20: 0.85714286
J21: Anthea Ann Lumen | K21: 0.99638448 | M21: Erika Ramos | N21: 0.9986532 | P21: Sandarah Cruz | Q21: 0.81170034
A22: Average of Attendance | B22: Column Labels | J22: Anthony Valdez | K22: 0.94736842 | M22: Jewel Mondina | N22: 0.95454545 | P22: Rhoda De Jesus | Q22: 0.97470539
A23: Row Labels | B23: Edmark Bania | C23: Vladimir Patio | D23: Grand Total | J23: Johnella Lopez | K23: 0.94107744 | M23: Karl Solomon | N23: 0.99657407 | P23: Edmark Bania | Q23: 0.95
A24: Rejection | B24: 0.92495614 | C24: 0.91596466 | D24: 0.92021064 | J24: Marion Vien Santos | K24: 0.76885522 | M24: Leo Olesco | N24: 1 | P24: Vladimir Patio | Q24: 0.99941077
A25: Grand Total | B25: 0.92495614 | C25: 0.91596466 | D25: 0.92021064 | J25: Mherica Santos | K25: 0.9962963 | M25: Mark Metra | N25: 0.73265107 | P25: Vladimir Patio | Q25: 0.91596466
J26: Ryan Rillo | K26: 0.91832359 | M26: Mayann Somera | N26: 1 | P26: Alyssa DeGuzman | Q26: 0.93249158
J27: Louis Cantillion | K27: 0.8902417 | M27: Rhoda De Jesus | N27: 0.9515873 | P27: Analyn Caniedo | Q27: 0.92306397
J28: Analyn Diaz | K28: 0.81548822 | M28: Hans Ruan | N28: 0.9515873 | P28: Arah Blancia | Q28: 0.86363636
J29: Angelo Agron | K29: 0.80714286 | M29: Grand Total | N29: 0.94771587 | P29: Avril Rie Son | Q29: 0.95084175
J30: Jesslyn Gatbunton | K30: 0.95917508 | P30: Bea Mercado | Q30: 0.9047619
J31: Lorraine Cabantac | K31: 0.89074074 | P31: Charlene Valdez | Q31: 0.9506734
J32: Patricia Busio | K32: 0.94964727 | P32: Charyselle Cadelina | Q32: 0.90664983
J33: Sean Edulan | K33: 0.94797178 | P33: Danielle Generao | Q33: 0.88203704
J34: Stephanie Del Rosario | K34: 0.86052189 | P34: Francis Alba | Q34: 0.94611111
J35: Theresa Ma Alvaro | K35: 0.89124579 | P35: Glessie DeJesus | Q35: 0.86363636
J36: Noemi Landerito | K36: 0.943054 | P36: Hanna Arceo | Q36: 0.90311448
J37: Femie DC Domenden | K37: 0.99671717 | P37: Iris Dahnielle Andalleon | Q37: 0.99920635
J38: Francis Narboneta | K38: 0.73395062 | P38: Jean Tan | Q38: 0.95446128
J39: Glory Nabayra | K39: 0.95260943 | P39: Jizelle Delos Reyes | Q39: 0.95454545
J40: Iverson Libranda | K40: 0.94183502 | P40: Joanna Cabrera | Q40: 0.93695286
J41: Joshua Joaquin | K41: 0.99991582 | P41: Mary Kilario | Q41: 0.95429293
...

Sheet MWeek 1
A1: Department | B1: Full Name | C1: State | D1: Thursday | E1: Friday | F1: Saturday | G1: Sunday | H1: Monday | I1: Tuesday | J1: Wednesday | K1: Thursday | L1: Friday | M1: Saturday | N1: Tardiness | O1: Absences | P1: Lost Hours | Q1: Target | R1: Completed | S1: Attendance | T1: VL | U1: LWOP | W1: Row Labels | X1: Sum of Tardiness | Y1: Sum of Absences | Z1: Sum of Completed | AA1: Sum of Target
A2: Billing | B2: Alexandra Ortiz | C2: KY | D2: 30 | E2: 97 | F2: RD | G2: RD | H2: P | I2: P | J2: P | K2: 47 | L2: P | M2: RD | N2: =SUM(D2,E2,K2) -> 174 | P2: =SUM(N2:O2) -> 174 | Q2: =450*7 -> 3150 | R2: =Q2-P2 -> 2976 | S2: =R2/Q2*100% -> 0.9447619 | W2: ALF | X2: 0 | Y2: 0 | Z2: 3150 | AA2: 3150
A3: Rejection | B3: Alyssa DeGuzman | C3: KY | D3: 12 | E3: P | F3: P | G3: P | H3: 450 | I3: RD | J3: RD | K3: 40 | L3: 30 | M3: P | N3: =SUM(D3,K3,L3) -> 82 | O3: =SUMIF(D3:M3,"540") -> 0 | P3: =SUM(N3:O3) -> 82 | Q3: =450*8 -> 3600 | R3: =Q3-P3 -> 3518 | S3: =R3/Q3*100% -> 0.97722222 | W3: Billing | X3: 2073 | Y3: 0 | Z3: 132027 | AA3: 134100
A4: Rejection | B4: Analyn Caniedo | C4: IL | D4: p | E4: 127 | F4: RD | G4: RD | H4: 450 | I4: RD | J4: RD | K4: 14 | L4: 4 | M4: 82 | N4: =SUM(E4,K4,L4,) -> 145 | O4: =SUMIF(D4:M4,"540") -> 0 | P4: =SUM(N4:O4) -> 145 | Q4: =450*6 -> 2700 | R4: =Q4-P4 -> 2555 | S4: =R4/Q4*100% -> 0.9462963 | W4: Intake | X4: 82 | Y4: 0 | Z4: 31418 | AA4: 31500
A5: Billing | B5: Analyn Diaz | C5: NJ | D5: P | E5: 15 | F5: RD | G5: RD | H5: P | I5: P | J5: P | K5: P | L5: 450 | M5: RD | N5: =E5 -> 15 | O5: =SUMIF(D5:M5,"540") -> 0 | P5: =SUM(N5:O5) -> 15 | Q5: =450*7 -> 3150 | R5: =Q5-P5 -> 3135 | S5: =R5/Q5*100% -> 0.9952381 | W5: Mpen | X5: 36 | Y5: 0 | Z5: 12114 | AA5: 12150
A6: Rejection | B6: Andrea Fonacier | C6: KY/IL | D6: P | E6: P | F6: RD | G6: RD | H6: P | I6: 4 | J6: P | K6: P | L6: 2 | M6: RD | N6: =SUM(I6,L6) -> 6 | P6: =SUM(N6:O6) -> 6 | Q6: =450*7 -> 3150 | R6: =Q6-P6 -> 3144 | S6: =R6/Q6*100% -> 0.99809524 | W6: Rebill | X6: 0 | Y6: 0 | Z6: 6300 | AA6: 6300
A7: Intake | B7: Angelica Bautista | C7: Multi | D7: RD | E7: RD | F7: P | G7: 47 | H7: P | I7: P | J7: P | K7: RD | L7: RD | M7: P | N7: =SUM(D7:M7) -> 47 | O7: =SUMIF(D7:M7,"540") -> 0 | P7: =SUM(N7:O7) -> 47 | Q7: =450*6 -> 2700 | R7: =Q7-P7 -> 2653 | S7: =R7/Q7*100% -> 0.98259259 | W7: Rejection | X7: 1012 | Y7: 0 | Z7: 119138 | AA7: 120150
A8: Billing | B8: Angelo Agron | C8: NJ | D8: P | E8: 450 | F8: RD | G8: RD | H8: P | I8: P | J8: P | K8: P | L8: P | M8: RD | N8: 0 | O8: =SUMIF(D8:M8,"540") -> 0 | P8: =SUM(N8:O8) -> 0 | Q8: =450*7 -> 3150 | R8: =Q8-P8 -> 3150 | S8: =R8/Q8*100% -> 1 | W8: Grand Total | X8: 3203 | Y8: 0 | Z8: 304147 | AA8: 307350
A9: Billing | B9: Anthea Ann Lumen | C9: KY | D9: P | E9: P | F9: RD | G9: RD | H9: P | I9: P | J9: P | K9: 10 | L9: P | M9: RD | N9: =K9 -> 10 | P9: =SUM(N9:O9) -> 10 | Q9: =450*7 -> 3150 | R9: =Q9-P9 -> 3140 | S9: =R9/Q9*100% -> 0.9968254
A10: Billing | B10: Anthony Valdez | C10: KY | D10: P | E10: P | F10: RD | G10: RD | H10: P | I10: P | J10: P | K10: P | L10: P | M10: RD | N10: 0 | O10: =SUMIF(D10:M10,"540") -> 0 | P10: =SUM(N10:O10) -> 0 | Q10: =450*7 -> 3150 | R10: =Q10-P10 -> 3150 | S10: =R10/Q10*100% -> 1
A11: Intake | B11: Ar Jean Tudtud | C11: Multi | D11: RD | E11: RD | F11: P | G11: P | H11: P | I11: P | J11: P | K11: RD | L11: RD | M11: P | N11: 0 | O11: =SUMIF(D11:M11,"540") -> 0 | P11: =SUM(N11:O11) -> 0 | Q11: =450*6 -> 2700 | R11: =Q11-P11 -> 2700 | S11: =R11/Q11*100% -> 1
A12: Rejection | B12: Arah Blancia | C12: IL | D12: RD | E12: P | F12: P | G12: P | H12: P | I12: 450 | J12: RD | K12: RD | L12: 450 | M12: P | N12: 0 | O12: =SUMIF(D12:M12,"540") -> 0 | P12: =SUM(N12:O12) -> 0 | Q12: =450*7 -> 3150 | R12: =Q12-P12 -> 3150 | S12: =R12/Q12*100% -> 1
A13: Rejection | B13: Audrey De Leon | C13: NJ | D13: P | E13: P | F13: RD | G13: RD | H13: P | I13: P | J13: P | K13: P | L13: RD | M13: RD | N13: 0 | O13: =SUMIF(D13:M13,"540") -> 0 | P13: =SUM(N13:O13) -> 0 | Q13: =450*7 -> 3150 | R13: =Q13-P13 -> 3150 | S13: =R13/Q13*100% -> 1
A14: Rejection | B14: Avril Rie Son | C14: NJ | D14: P | E14: P | F14: RD | G14: RD | H14: RD | I14: P | J14: P | K14: 5 | L14: P | M14: RD | N14: =K14 -> 5 | P14: =SUM(N14:O14) -> 5 | Q14: =450*7 -> 3150 | R14: =Q14-P14 -> 3145 | S14: =R14/Q14*100% -> 0.9984127
A15: Rejection | B15: Bea Mercado | C15: NJ | D15: P | E15: P | F15: RD | G15: RD | H15: P | I15: P | J15: P | K15: P | L15: LWOP | M15: RD | N15: 0 | O15: =SUMIF(D15:M15,"540") -> 0 | P15: =SUM(N15:O15) -> 0 | Q15: =450*6 -> 2700 | R15: =Q15-P15 -> 2700 | S15: =R15/Q15*100% -> 1 | U15: 1
A16: Rejection | B16: Charlene Valdez | C16: MA/NY/NJ (KY/IL) | D16: P | E16: P | F16: RD | G16: RD | H16: P | I16: 6 | J16: P | K16: P | L16: P | M16: RD | N16: =I16 -> 6 | P16: =SUM(N16:O16) -> 6 | Q16: =450*7 -> 3150 | R16: =Q16-P16 -> 3144 | S16: =R16/Q16*100% -> 0.99809524
A17: Rejection | B17: Charyselle Cadelina | C17: KY | D17: P | E17: 10 | F17: P | G17: P | H17: P | I17: P | J17: P | K17: P | L17: RD | M17: RD | N17: =SUM(D17:M17) -> 10 | O17: =SUMIF(D17:M17,"540") -> 0 | P17: =SUM(N17:O17) -> 10 | Q17: =450*8 -> 3600 | R17: =Q17-P17 -> 3590 | S17: =R17/Q17*100% -> 0.99722222
A18: Intake | B18: Collen Silapan | C18: Multi | D18: RD | E18: P | F18: P | G18: P | H18: P | I18: P | J18: RD | K18: RD | L18: 11 | M18: P | N18: =SUM(D18:M18) -> 11 | O18: =SUMIF(D18:M18,"540") -> 0 | P18: =SUM(N18:O18) -> 11 | Q18: =450*7 -> 3150 | R18: =Q18-P18 -> 3139 | S18: =R18/Q18*100% -> 0.99650794
A19: Rejection | B19: Danielle Generao | C19: KY | D19: P | E19: 28 | F19: RD | G19: RD | H19: 450 | I19: 8 | J19: 4 | K19: 2 | L19: 450 | M19: RD | N19: =SUM(E19,I19:K20) -> 42 | O19: =SUMIF(D19:M19,"540") -> 0 | P19: =SUM(N19:O19) -> 42 | Q19: =450*7 -> 3150 | R19: =Q19-P19 -> 3108 | S19: =R19/Q19*100% -> 0.98666667
A20: Rejection | B20: Edmark Bania | C20: Multi | D20: P | E20: VL | F20: VL | G20: RD | H20: RD | I20: P | J20: P | K20: P | L20: P | M20: RD | N20: 0 | O20: =SUMIF(D20:M20,"540") -> 0 | P20: =SUM(N20:O20) -> 0 | Q20: =450*5 -> 2250 | R20: =Q20-P20 -> 2250 | S20: =R20/Q20*100% -> 1 | T20: 2
A21: Billing | B21: Eldrick Loreno | C21: NY | D21: P | E21: 328 | F21: RD | G21: RD | H21: VL | I21: P | J21: P | K21: P | L21: 30 | M21: RD | N21: =SUM(E21,L21) -> 358 | P21: =SUM(N21:O21) -> 358 | Q21: =450*6 -> 2700 | R21: =Q21-P21 -> 2342 | S21: =R21/Q21*100% -> 0.86740741 | T21: 1
A22: Rebill | B22: Erika Ramos | C22: Multi | D22: P | E22: P | F22: RD | G22: RD | H22: P | I22: P | J22: P | K22: P | L22: P | M22: RD | N22: 0 | O22: =SUMIF(D22:M22,"540") -> 0 | P22: =SUM(N22:O22) -> 0 | Q22: =450*7 -> 3150 | R22: =Q22-P22 -> 3150 | S22: =R22/Q22*100% -> 1
A23: Billing | B23: Ethel Gregorio | C23: MA | D23: 450 | E23: 19 | F23: RD | G23: RD | H23: P | I23: 450 | J23: P | K23: 9 | L23: 27 | M23: RD | N23: =SUM(E23,K23,L23) -> 55 | O23: =SUMIF(D23:M23,"540") -> 0 | P23: =SUM(N23:O23) -> 55 | Q23: =450*7 -> 3150 | R23: =Q23-P23 -> 3095 | S23: =R23/Q23*100% -> 0.98253968
A24: Billing | B24: Eunice Bargo | C24: MA | D24: 6 | E24: 19 | F24: RD | G24: RD | H24: 450 | I24: 9 | J24: P | K24: P | L24: 2 | M24: RD | N24: =SUM(D24,E24,I24,L24) -> 36 | O24: =SUMIF(D24:M24,"540") -> 0 | P24: =SUM(N24:O24) -> 36 | Q24: =450*7 -> 3150 | R24: =Q24-P24 -> 3114 | S24: =R24/Q24*100% -> 0.98857143
A25: Rejection | B25: Eunice Padadnan | C25: NY | D25: RD | E25: P | F25: P | G25: P | H25: P | I25: RD | J25: P | K25: P | L25: P | M25: P | N25: 0 | O25: =SUMIF(D25:M25,"540") -> 0 | P25: =SUM(N25:O25) -> 0 | Q25: =450*8 -> 3600 | R25: =Q25-P25 -> 3600 | S25: =R25/Q25*100% -> 1
A26: Billing | B26: Femie DC Domenden | C26: IL | D26: P | E26: 1 | F26: RD | G26: RD | H26: P | I26: P | J26: P | K26: P | L26: 35 | M26: RD | N26: =SUM(E26,L26) -> 36 | O26: =SUMIF(D26:M26,"540") -> 0 | P26: =SUM(N26:O26) -> 36 | Q26: =450*7 -> 3150 | R26: =Q26-P26 -> 3114 | S26: =R26/Q26*100% -> 0.98857143
A27: Rejection | B27: Francis Alba | C27: Multi | D27: P | E27: VL | F27: RD | G27: RD | H27: VL | I27: 40 | J27: P | K27: P | L27: P | M27: RD | N27: =SUM(I27) -> 40 | O27: =SUMIF(D27:M27,"540") -> 0 | P27: =SUM(N27:O27) -> 40 | Q27: =450*5 -> 2250 | R27: =Q27-P27 -> 2210 | S27: =R27/Q27*100% -> 0.98222222 | T27: 2
A28: Billing | B28: Francis Narboneta | C28: IL | D28: P | E28: 299 | F28: RD | G28: RD | H28: P | I28: 17 | J28: 1 | K28: 450 | L28: 450 | M28: RD | N28: =SUM(E28,I28,J28) -> 317 | O28: =SUMIF(D28:M28,"540") -> 0 | P28: =SUM(N28:O28) -> 317 | Q28: =450*7 -> 3150 | R28: =Q28-P28 -> 2833 | S28: =R28/Q28*100% -> 0.89936508
A29: Billing | B29: Gladys Astilla | C29: MA | D29: P | E29: 12 | F29: RD | G29: RD | H29: P | I29: P | J29: P | K29: P | L29: P | M29: RD | N29: =E29 -> 12 | O29: =SUMIF(D29:M29,"540") -> 0 | P29: =SUM(N29:O29) -> 12 | Q29: =450*7 -> 3150 | R29: =Q29-P29 -> 3138 | S29: =R29/Q29*100% -> 0.99619048
A30: Rejection | B30: Glessie DeJesus | C30: KY | D30: P | E30: P | F30: RD | G30: RD | H30: P | I30: P | J30: P | K30: P | L30: P | M30: RD | N30: 0 | O30: =SUMIF(D30:M30,"540") -> 0 | P30: =SUM(N30:O30) -> 0 | Q30: =450*7 -> 3150 | R30: =Q30-P30 -> 3150 | S30: =R30/Q30*100% -> 1
A31: Billing | B31: Glory Nabayra | C31: IL | D31: 8 | E31: P | F31: RD | G31: RD | H31: P | I31: P | J31: P | K31: P | L31: P | M31: RD | N31: =D31 -> 8 | O31: =SUMIF(D31:M31,"540") -> 0 | P31: =SUM(N31:O31) -> 8 | Q31: =450*7 -> 3150 | R31: =Q31-P31 -> 3142 | S31: =R31/Q31*100% -> 0.99746032
A32: Rejection | B32: Hanna Arceo | C32: KY | D32: P | E32: P | F32: RD | G32: RD | H32: 450 | I32: P | J32: P | K32: 4 | L32: 12 | M32: RD | N32: =SUM(K32,L32) -> 16 | O32: =SUMIF(D32:M32,"540") -> 0 | P32: =SUM(N32:O32) -> 16 | Q32: =450*7 -> 3150 | R32: =Q32-P32 -> 3134 | S32: =R32/Q32*100% -> 0.99492063
A33: Mpen | B33: Hans Ruan | C33: Multi | D33: P | E33: P | F33: RD | G33: RD | H33: P | I33: P | J33: P | K33: P | L33: P | M33: RD | N33: 0 | O33: =SUMIF(D33:M33,"540") -> 0 | P33: =SUM(N33:O33) -> 0 | Q33: =450*7 -> 3150 | R33: =Q33-P33 -> 3150 | S33: =R33/Q33*100% -> 1
A34: Intake | B34: Hazelyn Rodrigo | C34: Multi | D34: P | E34: P | F34: RD | G34: RD | H34: P | I34: P | J34: P | K34: P | L34: P | M34: RD | N34: 0 | O34: =SUMIF(D34:M34,"540") -> 0 | P34: =SUM(N34:O34) -> 0 | Q34: =450*7 -> 3150 | R34: =Q34-P34 -> 3150 | S34: =R34/Q34*100% -> 1
A35: Rejection | B35: Iris Dahnielle Andalleon | C35: Multi | D35: RD | E35: P | F35: VL | G35: P | H35: P | I35: P | J35: RD | K35: RD | L35: P | M35: P | N35: 0 | O35: =SUMIF(D35:M35,"540") -> 0 | P35: =SUM(N35:O35) -> 0 | Q35: =450*6 -> 2700 | R35: =Q35-P35 -> 2700 | S35: =R35/Q35*100% -> 1 | T35: 1
A36: Intake | B36: Isabela Arellano | C36: Multi | D36: P | E36: P | F36: RD | G36: RD | H36: P | I36: P | J36: 13 | K36: P | L36: 5 | M36: RD | N36: =SUM(J36:L36) -> 18 | O36: =SUMIF(D36:M36,"540") -> 0 | P36: =SUM(N36:O36) -> 18 | Q36: =450*7 -> 3150 | R36: =Q36-P36 -> 3132 | S36: =R36/Q36*100% -> 0.99428571
A37: Billing | B37: Iverson Libranda | C37: IL | D37: P | E37: P | F37: RD | G37: RD | H37: P | I37: P | J37: P | K37: P | L37: P | M37: RD | N37: 0 | O37: =SUMIF(D37:M37,"540") -> 0 | P37: =SUM(N37:O37) -> 0 | Q37: =450*7 -> 3150 | R37: =Q37-P37 -> 3150 | S37: =R37/Q37*100% -> 1
A38: Billing | B38: Jason Cruz | C38: MA | D38: P | E38: P | F38: RD | G38: RD | H38: 450 | I38: P | J38: P | K38: P | L38: P | M38: RD | N38: 0 | O38: =SUMIF(D38:M38,"540") -> 0 | P38: =SUM(N38:O38) -> 0 | Q38: =450*7 -> 3150 | R38: =Q38-P38 -> 3150 | S38: =R38/Q38*100% -> 1
A39: Rejection | B39: Jean Tan | C39: NY NJ | D39: P | E39: P | F39: RD | G39: RD | H39: P | I39: P | J39: P | K39: P | L39: P | M39: RD | N39: 0 | O39: =SUMIF(D39:M39,"540") -> 0 | P39: =SUM(N39:O39) -> 0 | Q39: =450*7 -> 3150 | R39: =Q39-P39 -> 3150 | S39: =R39/Q39*100% -> 1
A40: Rejection | B40: Jeannie Bajaro | C40: Multi | D40: P | E40: P | F40: P | G40: P | H40: P | I40: RD | J40: RD | K40: P | L40: P | M40: P | N40: 0 | O40: =SUMIF(D40:M40,"540") -> 0 | P40: =SUM(N40:O40) -> 0 | Q40: =450*8 -> 3600 | R40: =Q40-P40 -> 3600 | S40: =R40/Q40*100% -> 1
...

Sheet MWeek 2
A1: Department | B1: Full Name | C1: State | D1: Sunday | E1: Monday | F1: Tuesday | G1: Wednesday | H1: Thursday | I1: Friday | J1: Saturday | K1: Tardiness | L1: Absences | M1: Lost Hours | N1: Target | O1: Completed | P1: Attendance | Q1: VL | R1: LWOP | T1: Row Labels | U1: Sum of Tardiness | V1: Sum of Absences | W1: Sum of Completed | X1: Sum of Target
A2: Billing | B2: Alexandra Ortiz | C2: KY | D2: RD | E2: 450 | F2: 450 | G2: 450 | H2: P | I2: P | J2: RD | L2: =SUMIF(A2:J2,"450") -> 1350 | M2: =SUM(K2:L2) -> 1350 | N2: =450*5 -> 2250 | O2: =N2-M2 -> 900 | P2: =O2/N2*100% -> 0.4 | T2: ALF | V2: 0 | W2: 2250 | X2: 2250
A3: Rejection | B3: Alyssa DeGuzman | C3: KY | D3: P | E3: 44 | F3: RD | G3: RD | H3: P | I3: 2 | J3: 14 | K3: =SUM(D3:J3) -> 60 | L3: =SUMIF(A3:J3,"450") -> 0 | M3: =SUM(K3:L3) -> 60 | N3: =450*5 -> 2250 | O3: =N3-M3 -> 2190 | P3: =O3/N3*100% -> 0.97333333 | T3: Billing | U3: 917 | V3: 8550 | W3: 79183 | X3: 88650
A4: Rejection | B4: Analyn Caniedo | C4: IL | D4: 7 | E4: P | F4: RD | G4: RD | H4: P | I4: P | J4: P | K4: =SUM(D4:J4) -> 7 | L4: =SUMIF(A4:J4,"450") -> 0 | M4: =SUM(K4:L4) -> 7 | N4: =450*5 -> 2250 | O4: =N4-M4 -> 2243 | P4: =O4/N4*100% -> 0.99688889 | T4: Intake | U4: 408 | V4: 0 | W4: 20292 | X4: 20700
A5: Billing | B5: Analyn Diaz | C5: NJ | D5: RD | E5: P | F5: 450 | G5: P | H5: 450 | I5: 5 | J5: RD | K5: =I5 -> 5 | L5: =SUMIF(A5:J5,"450") -> 900 | M5: =SUM(K5:L5) -> 905 | N5: =450*5 -> 2250 | O5: =N5-M5 -> 1345 | P5: =O5/N5*100% -> 0.59777778 | T5: Mpen | U5: 36 | V5: 1350 | W5: 6264 | X5: 7650
A6: Rejection | B6: Andrea Fonacier | C6: KY/IL | D6: RD | E6: P | F6: P | G6: 6 | H6: 7 | I6: 7 | J6: RD | K6: =SUM(D6:J6) -> 20 | L6: =SUMIF(A6:J6,"450") -> 0 | M6: =SUM(K6:L6) -> 20 | N6: =450*5 -> 2250 | O6: =N6-M6 -> 2230 | P6: =O6/N6*100% -> 0.99111111 | T6: Rebill | V6: 0 | W6: 4500 | X6: 4500
A7: Intake | B7: Angelica Bautista | C7: Multi | D7: P | E7: P | F7: P | G7: P | H7: P | I7: RD | J7: RD | L7: =SUMIF(A7:J7,"450") -> 0 | M7: =SUM(K7:L7) -> 0 | N7: =450*5 -> 2250 | O7: =N7-M7 -> 2250 | P7: =O7/N7*100% -> 1 | T7: Rejection | U7: 718 | V7: 5400 | W7: 78032 | X7: 84150
A8: Billing | B8: Angelo Agron | C8: NJ | D8: RD | E8: 450 | F8: P | G8: 3 | H8: 2 | I8: 2 | J8: RD | K8: =SUM(G8,H8,I8) -> 7 | L8: =SUMIF(A8:J8,"450") -> 450 | M8: =SUM(K8:L8) -> 457 | N8: =450*5 -> 2250 | O8: =N8-M8 -> 1793 | P8: =O8/N8*100% -> 0.79688889 | T8: Grand Total | U8: 2079 | V8: 15300 | W8: 190521 | X8: 207900
A9: Billing | B9: Anthea Ann Lumen | C9: KY | D9: RD | E9: P | F9: LWOP | G9: P | H9: P | I9: P | J9: RD | L9: =SUMIF(A9:J9,"450") -> 0 | M9: =SUM(K9:L9) -> 0 | N9: =450*4 -> 1800 | O9: =N9-M9 -> 1800 | P9: =O9/N9*100% -> 1 | R9: 1
A10: Billing | B10: Anthony Valdez | C10: KY | D10: RD | E10: P | F10: P | G10: 450 | H10: P | I10: VL | J10: RD | L10: =SUMIF(A10:J10,"450") -> 450 | M10: =SUM(K10:L10) -> 450 | N10: =450*4 -> 1800 | O10: =N10-M10 -> 1350 | P10: =O10/N10*100% -> 0.75 | Q10: 1
A11: Intake | B11: Ar Jean Tudtud | C11: Multi | D11: P | E11: RD | F11: P | G11: P | H11: P | I11: P | J11: P | L11: =SUMIF(A11:J11,"450") -> 0 | M11: =SUM(K11:L11) -> 0 | N11: =450*5 -> 2250 | O11: =N11-M11 -> 2250 | P11: =O11/N11*100% -> 1
A12: Rejection | B12: Arah Blancia | C12: IL | D12: P | E12: 450 | F12: P | G12: RD | H12: RD | I12: P | J12: P | L12: =SUMIF(A12:J12,"450") -> 450 | M12: =SUM(K12:L12) -> 450 | N12: =450*5 -> 2250 | O12: =N12-M12 -> 1800 | P12: =O12/N12*100% -> 0.8
A13: Rejection | B13: Audrey De Leon | C13: NJ | D13: P | E13: P | F13: P | G13: P | H13: P | I13: RD | J13: RD | L13: =SUMIF(A13:J13,"450") -> 0 | M13: =SUM(K13:L13) -> 0 | N13: =450*5 -> 2250 | O13: =N13-M13 -> 2250 | P13: =O13/N13*100% -> 1
A14: Rejection | B14: Avril Rie Son | C14: NJ | D14: RD | E14: 5 | F14: 7 | G14: P | H14: P | I14: P | J14: RD | K14: =SUM(D14:J14) -> 12 | L14: =SUMIF(A14:J14,"450") -> 0 | M14: =SUM(K14:L14) -> 12 | N14: =450*5 -> 2250 | O14: =N14-M14 -> 2238 | P14: =O14/N14*100% -> 0.99466667
A15: Rejection | B15: Bea Mercado | C15: NJ | D15: RD | E15: 450 | F15: P | G15: P | H15: P | I15: P | J15: RD | L15: =SUMIF(A15:J15,"450") -> 450 | M15: =SUM(K15:L15) -> 450 | N15: =450*5 -> 2250 | O15: =N15-M15 -> 1800 | P15: =O15/N15*100% -> 0.8
A16: Rejection | B16: Charlene Valdez | C16: MA/NY/NJ (KY/IL) | D16: RD | E16: P | F16: P | G16: 19 | H16: P | I16: 21 | J16: RD | K16: =SUM(D16:J16) -> 40 | L16: =SUMIF(A16:J16,"450") -> 0 | M16: =SUM(K16:L16) -> 40 | N16: =450*5 -> 2250 | O16: =N16-M16 -> 2210 | P16: =O16/N16*100% -> 0.98222222
A17: Rejection | B17: Charyselle Cadelina | C17: KY | D17: RD | E17: P | F17: P | G17: P | H17: P | I17: 17 | J17: RD | K17: =SUM(D17:J17) -> 17 | L17: =SUMIF(A17:J17,"450") -> 0 | M17: =SUM(K17:L17) -> 17 | N17: =450*5 -> 2250 | O17: =N17-M17 -> 2233 | P17: =O17/N17*100% -> 0.99244444
A18: Intake | B18: Collen Silapan | C18: Multi | D18: LWOP | E18: P | F18: P | G18: P | H18: P | I18: RD | J18: RD | L18: =SUMIF(A18:J18,"450") -> 0 | M18: =SUM(K18:L18) -> 0 | N18: =450*4 -> 1800 | O18: =N18-M18 -> 1800 | P18: =O18/N18*100% -> 1 | R18: 1
A19: Rejection | B19: Danielle Generao | C19: KY | D19: RD | E19: P | F19: 22 | G19: P | H19: 23 | I19: P | J19: RD | K19: =SUM(D19:J19) -> 45 | L19: =SUMIF(A19:J19,"450") -> 0 | M19: =SUM(K19:L19) -> 45 | N19: =450*5 -> 2250 | O19: =N19-M19 -> 2205 | P19: =O19/N19*100% -> 0.98
A20: Rejection | B20: Edmark Bania | C20: Multi | D20: RD | E20: P | F20: P | G20: P | H20: P | I20: P | J20: RD | L20: =SUMIF(A20:J20,"450") -> 0 | M20: =SUM(K20:L20) -> 0 | N20: =450*5 -> 2250 | O20: =N20-M20 -> 2250 | P20: =O20/N20*100% -> 1
A21: Billing | B21: Eldrick Loreno | C21: NY | D21: RD | E21: P | F21: P | G21: 450 | H21: P | I21: P | J21: RD | L21: =SUMIF(A21:J21,"450") -> 450 | M21: =SUM(K21:L21) -> 450 | N21: =450*5 -> 2250 | O21: =N21-M21 -> 1800 | P21: =O21/N21*100% -> 0.8
A22: Rebill | B22: Erika Ramos | C22: Multi | D22: RD | E22: P | F22: P | G22: P | H22: P | I22: P | J22: RD | L22: =SUMIF(A22:J22,"450") -> 0 | M22: =SUM(K22:L22) -> 0 | N22: =450*5 -> 2250 | O22: =N22-M22 -> 2250 | P22: =O22/N22*100% -> 1
A23: Billing | B23: Ethel Gregorio | C23: MA | D23: RD | E23: 15 | F23: 20 | G23: 11 | H23: 15 | I23: 14 | J23: RD | K23: =SUM(D23:J23) -> 75 | L23: =SUMIF(A23:J23,"450") -> 0 | M23: =SUM(K23:L23) -> 75 | N23: =450*5 -> 2250 | O23: =N23-M23 -> 2175 | P23: =O23/N23*100% -> 0.96666667
A24: Billing | B24: Eunice Bargo | C24: MA | D24: RD | E24: P | F24: 8 | G24: 19 | H24: P | I24: P | J24: RD | K24: =SUM(D24:J24) -> 27 | L24: =SUMIF(A24:J24,"450") -> 0 | M24: =SUM(K24:L24) -> 27 | N24: =450*5 -> 2250 | O24: =N24-M24 -> 2223 | P24: =O24/N24*100% -> 0.988
A25: Rejection | B25: Eunice Padadnan | C25: NY | D25: RD | E25: 1 | F25: P | G25: P | H25: P | I25: P | J25: RD | K25: =SUM(D25:J25) -> 1 | L25: =SUMIF(A25:J25,"450") -> 0 | M25: =SUM(K25:L25) -> 1 | N25: =450*5 -> 2250 | O25: =N25-M25 -> 2249 | P25: =O25/N25*100% -> 0.99955556
A26: Billing | B26: Femie DC Domenden | C26: IL | D26: RD | E26: P | F26: P | G26: P | H26: P | I26: 3 | J26: RD | K26: =SUM(D26:J26) -> 3 | L26: =SUMIF(A26:J26,"450") -> 0 | M26: =SUM(K26:L26) -> 3 | N26: =450*5 -> 2250 | O26: =N26-M26 -> 2247 | P26: =O26/N26*100% -> 0.99866667
A27: Rejection | B27: Francis Alba | C27: Multi | D27: RD | E27: P | F27: P | G27: P | H27: P | I27: P | J27: RD | L27: =SUMIF(A27:J27,"450") -> 0 | M27: =SUM(K27:L27) -> 0 | N27: =450*5 -> 2250 | O27: =N27-M27 -> 2250 | P27: =O27/N27*100% -> 1
A28: Billing | B28: Francis Narboneta | C28: IL | D28: RD | E28: 450 | F28: 450 | G28: 450 | H28: P | I28: P | J28: RD | L28: =SUMIF(A28:J28,"450") -> 1350 | M28: =SUM(K28:L28) -> 1350 | N28: =450*5 -> 2250 | O28: =N28-M28 -> 900 | P28: =O28/N28*100% -> 0.4
A29: Billing | B29: Gladys Astilla | C29: MA | D29: RD | E29: VL | F29: P | G29: P | H29: P | I29: P | J29: RD | L29: =SUMIF(A29:J29,"450") -> 0 | M29: =SUM(K29:L29) -> 0 | N29: =450*4 -> 1800 | O29: =N29-M29 -> 1800 | P29: =O29/N29*100% -> 1 | Q29: 1
A30: Rejection | B30: Glessie DeJesus | C30: KY | D30: RD | E30: 450 | F30: P | G30: P | H30: P | I30: P | J30: RD | L30: =SUMIF(A30:J30,"450") -> 450 | M30: =SUM(K30:L30) -> 450 | N30: =450*5 -> 2250 | O30: =N30-M30 -> 1800 | P30: =O30/N30*100% -> 0.8
A31: Billing | B31: Glory Nabayra | C31: IL | D31: RD | E31: P | F31: P | G31: P | H31: P | I31: P | J31: RD | L31: =SUMIF(A31:J31,"450") -> 0 | M31: =SUM(K31:L31) -> 0 | N31: =450*5 -> 2250 | O31: =N31-M31 -> 2250 | P31: =O31/N31*100% -> 1
A32: Rejection | B32: Hanna Arceo | C32: KY | D32: RD | E32: 1 | F32: 1 | G32: 450 | H32: P | I32: P | J32: RD | K32: =E32+F32 -> 2 | L32: =SUMIF(A32:J32,"450") -> 450 | M32: =SUM(K32:L32) -> 452 | N32: =450*5 -> 2250 | O32: =N32-M32 -> 1798 | P32: =O32/N32*100% -> 0.79911111
A33: Mpen | B33: Hans Ruan | C33: Multi | D33: RD | E33: P | F33: P | G33: P | H33: P | I33: P | J33: RD | L33: =SUMIF(A33:J33,"450") -> 0 | M33: =SUM(K33:L33) -> 0 | N33: =450*5 -> 2250 | O33: =N33-M33 -> 2250 | P33: =O33/N33*100% -> 1
A34: Intake | B34: Hazelyn Rodrigo | C34: Multi | D34: RD | E34: 56 | F34: RD | G34: RD | H34: P | I34: P | J34: 65 | K34: =SUM(D34:J34) -> 121 | L34: =SUMIF(A34:J34,"450") -> 0 | M34: =SUM(K34:L34) -> 121 | N34: =450*4 -> 1800 | O34: =N34-M34 -> 1679 | P34: =O34/N34*100% -> 0.93277778
A35: Rejection | B35: Iris Dahnielle Andalleon | C35: Multi | D35: P | E35: P | F35: P | G35: RD | H35: RD | I35: P | J35: P | L35: =SUMIF(A35:J35,"450") -> 0 | M35: =SUM(K35:L35) -> 0 | N35: =450*5 -> 2250 | O35: =N35-M35 -> 2250 | P35: =O35/N35*100% -> 1
A36: Intake | B36: Isabela Arellano | C36: Multi | D36: RD | E36: 10 | F36: 270 | G36: P | H36: 1 | I36: LWOP | J36: RD | K36: =SUM(D36:J36) -> 281 | L36: =SUMIF(A36:J36,"450") -> 0 | M36: =SUM(K36:L36) -> 281 | N36: =450*4 -> 1800 | O36: =N36-M36 -> 1519 | P36: =O36/N36*100% -> 0.84388889 | R36: 1
A37: Billing | B37: Iverson Libranda | C37: IL | D37: RD | E37: P | F37: 9 | G37: P | H37: P | I37: P | J37: RD | K37: =SUM(D37:J37) -> 9 | L37: =SUMIF(A37:J37,"450") -> 0 | M37: =SUM(K37:L37) -> 9 | N37: =450*5 -> 2250 | O37: =N37-M37 -> 2241 | P37: =O37/N37*100% -> 0.996
A38: Billing | B38: Jason Cruz | C38: MA | D38: RD | E38: P | F38: P | G38: P | H38: VL | I38: VL | J38: RD | L38: =SUMIF(A38:J38,"450") -> 0 | M38: =SUM(K38:L38) -> 0 | N38: =450*3 -> 1350 | O38: =N38-M38 -> 1350 | P38: =O38/N38*100% -> 1 | Q38: 2
A39: Rejection | B39: Jean Tan | C39: NY NJ | D39: RD | E39: P | F39: P | G39: P | H39: P | I39: 450 | J39: RD | L39: =SUMIF(A39:J39,"450") -> 450 | M39: =SUM(K39:L39) -> 450 | N39: =450*5 -> 2250 | O39: =N39-M39 -> 1800 | P39: =O39/N39*100% -> 0.8
A40: Rejection | B40: Jeannie Bajaro | C40: Multi | D40: P | E40: P | F40: RD | G40: RD | H40: VL | I40: P | J40: P | L40: =SUMIF(A40:J40,"450") -> 0 | M40: =SUM(K40:L40) -> 0 | N40: =450*4 -> 1800 | O40: =N40-M40 -> 1800 | P40: =O40/N40*100% -> 1 | Q40: 1
...

Sheet JWeek2
A1: Department | B1: Full Name | C1: State | D1: SUNDAY | E1: MONDAY | F1: TUESDAY | G1: WEDNESDAY | H1: THURSDAY | I1: FRIDAY | J1: SATURDAY | K1: Tardiness | L1: Absences | M1: Lost Hours | N1: Target | O1: Completed | P1: Attendance | Q1: VL | R1: LWOP | T1: Row Labels | U1: Sum of Tardiness | V1: Sum of Absences | W1: Sum of Lost Hours | X1: Sum of Completed | Y1: Sum of Target | Z1: Average of Attendance
A2: Billing | B2: Alexandra Ortiz | C2: KY | D2: RD | E2: P | F2: 106 | G2: P | H2: P | I2: LWOP | J2: RD | K2: =SUM(F2:I2) -> 106 | L2: =SUMIF(D2:J2,"450") -> 0 | M2: =SUM(K2:L2) -> 106 | N2: =450*4 -> 1800 | O2: =N2-M2 -> 1694 | P2: =O2/N2*100% -> 0.94111111 | R2: 1 | T2: ALF | U2: 0 | V2: 0 | W2: 0 | X2: 2250 | Y2: 2250 | Z2: 1
A3: Rejection | B3: Alyssa DeGuzman | C3: KY | D3: P | E3: P | F3: RD | G3: RD | H3: 450 | I3: 7 | J3: P | K3: =I3 -> 7 | L3: =SUMIF(D3:J3,"450") -> 450 | M3: =SUM(K3:L3) -> 457 | N3: =450*5 -> 2250 | O3: =N3-M3 -> 1793 | P3: =O3/N3*100% -> 0.79688889 | T3: Billing | U3: 1617 | V3: 4950 | W3: 6567 | X3: 81183 | Y3: 87750 | Z3: 0.92668056
A4: Rejection | B4: Analyn Caniedo | C4: IL | D4: P | E4: P | F4: RD | G4: RD | H4: P | I4: 2 | J4: P | K4: =SUM(D4:J4) -> 2 | L4: =SUMIF(D4:J4,"450") -> 0 | M4: =SUM(K4:L4) -> 2 | N4: =450*5 -> 2250 | O4: =N4-M4 -> 2248 | P4: =O4/N4*100% -> 0.99911111 | T4: Intake | U4: 491 | V4: 450 | W4: 941 | X4: 21109 | Y4: 22050 | Z4: 0.95551111
A5: Billing | B5: Analyn Diaz | C5: NJ | D5: RD | E5: 6 | F5: 4 | G5: 48 | H5: P | I5: P | J5: RD | K5: =SUM(E5:I5) -> 58 | L5: =SUMIF(D5:J5,"450") -> 0 | M5: =SUM(K5:L5) -> 58 | N5: =450*5 -> 2250 | O5: =N5-M5 -> 2192 | P5: =O5/N5*100% -> 0.97422222 | T5: Mpen | U5: 0 | V5: 900 | W5: 900 | X5: 7650 | Y5: 8550 | Z5: 0.9
A6: Rejection | B6: Andrea Fonacier | C6: KY/IL | D6: RD | E6: 16 | F6: P | G6: P | H6: 5 | I6: 11 | J6: RD | K6: =SUM(D6:J6) -> 32 | L6: =SUMIF(D6:J6,"450") -> 0 | M6: =SUM(K6:L6) -> 32 | N6: =450*5 -> 2250 | O6: =N6-M6 -> 2218 | P6: =O6/N6*100% -> 0.98577778 | T6: Rebill | U6: 0 | V6: 0 | W6: 0 | X6: 4500 | Y6: 4500 | Z6: 1
A7: Intake | B7: Angelica Bautista | C7: Multi | D7: P | E7: P | F7: P | G7: P | H7: P | I7: RD | J7: RD | K7: =SUM(D7:J7) -> 0 | L7: =SUMIF(D7:J7,"450") -> 0 | M7: =SUM(K7:L7) -> 0 | N7: =450*5 -> 2250 | O7: =N7-M7 -> 2250 | P7: =O7/N7*100% -> 1 | T7: Rejection | U7: 552 | V7: 2700 | W7: 3252 | X7: 77748 | Y7: 81000 | Z7: 0.95985185
A8: Billing | B8: Angelo Agron | C8: NJ | D8: RD | E8: 13 | F8: LWOP | G8: P | H8: P | I8: P | J8: RD | K8: =SUM(E8:I8) -> 13 | L8: =SUMIF(D8:J8,"450") -> 0 | M8: =SUM(K8:L8) -> 13 | N8: =450*4 -> 1800 | O8: =N8-M8 -> 1787 | P8: =O8/N8*100% -> 0.99277778 | T8: Grand Total | U8: 2660 | V8: 9000 | W8: 11660 | X8: 194440 | Y8: 206100 | Z8: 0.94383871
A9: Billing | B9: Anthea Ann Lumen | C9: KY | D9: RD | E9: P | F9: 6 | G9: P | H9: P | I9: 115 | J9: RD | K9: =SUM(D9:I9) -> 121 | L9: =SUMIF(D9:J9,"450") -> 0 | M9: =SUM(K9:L9) -> 121 | N9: =450*5 -> 2250 | O9: =N9-M9 -> 2129 | P9: =O9/N9*100% -> 0.94622222
A10: Billing | B10: Anthony Valdez | C10: KY | D10: RD | E10: P | F10: P | G10: P | H10: P | I10: P | J10: RD | K10: =SUM(D10:I10) -> 0 | L10: =SUMIF(D10:J10,"450") -> 0 | M10: =SUM(K10:L10) -> 0 | N10: =450*5 -> 2250 | O10: =N10-M10 -> 2250 | P10: =O10/N10*100% -> 1
A11: Intake | B11: Ar Jean Tudtud | C11: Multi | D11: RD | E11: RD | F11: P | G11: P | H11: P | I11: P | J11: P | K11: =SUM(D11:I11) -> 0 | L11: =SUMIF(D11:J11,"450") -> 0 | M11: =SUM(K11:L11) -> 0 | N11: =450*5 -> 2250 | O11: =N11-M11 -> 2250 | P11: =O11/N11*100% -> 1 | T11: Row Labels | U11: Average of Attendance
A12: Rejection | B12: Arah Blancia | C12: IL | D12: P | E12: P | F12: P | G12: RD | H12: RD | I12: P | J12: P | K12: =SUM(D12:J12) -> 0 | L12: =SUMIF(D12:J12,"450") -> 0 | M12: =SUM(K12:L12) -> 0 | N12: =450*5 -> 2250 | O12: =N12-M12 -> 2250 | P12: =O12/N12*100% -> 1 | T12: Rejection | U12: 0.95985185
A13: Rejection | B13: Avril Rie Son | C13: NJ | D13: RD | E13: 16 | F13: P | G13: 26 | H13: P | I13: 6 | J13: RD | L13: =SUMIF(D13:J13,"450") -> 0 | M13: =SUM(K13:L13) -> 0 | N13: =450*5 -> 2250 | O13: =N13-M13 -> 2250 | P13: =O13/N13*100% -> 1 | T13: Alyssa DeGuzman | U13: 0.79688889
A14: Rejection | B14: Bea Mercado | C14: NJ | D14: RD | E14: P | F14: P | G14: P | H14: P | I14: P | J14: RD | K14: =SUM(D14:J14) -> 0 | L14: =SUMIF(D14:J14,"450") -> 0 | M14: =SUM(K14:L14) -> 0 | N14: =450*5 -> 2250 | O14: =N14-M14 -> 2250 | P14: =O14/N14*100% -> 1 | T14: Analyn Caniedo | U14: 0.99911111
A15: Rejection | B15: Charlene Valdez | C15: MA/NY/NJ (KY/IL) | D15: RD | E15: P | F15: P | G15: P | H15: P | I15: P | J15: RD | K15: =SUM(D15:J15) -> 0 | L15: =SUMIF(D15:J15,"450") -> 0 | M15: =SUM(K15:L15) -> 0 | N15: =450*5 -> 2250 | O15: =N15-M15 -> 2250 | P15: =O15/N15*100% -> 1 | T15: Andrea Fonacier | U15: 0.98577778
A16: Rejection | B16: Charyselle Cadelina | C16: KY | D16: RD | E16: 4 | F16: 9 | G16: P | H16: P | I16: 1 | J16: RD | K16: =SUM(D16:J16) -> 14 | L16: =SUMIF(D16:J16,"450") -> 0 | M16: =SUM(K16:L16) -> 14 | N16: =450*5 -> 2250 | O16: =N16-M16 -> 2236 | P16: =O16/N16*100% -> 0.99377778 | T16: Arah Blancia | U16: 1
A17: Intake | B17: Collen Silapan | C17: Multi | D17: P | E17: P | F17: P | G17: P | H17: P | I17: RD | J17: RD | K17: =SUM(D17:J17) -> 0 | L17: =SUMIF(D17:J17,"450") -> 0 | M17: =SUM(K17:L17) -> 0 | N17: =450*5 -> 2250 | O17: =N17-M17 -> 2250 | P17: =O17/N17*100% -> 1 | T17: Avril Rie Son | U17: 1
A18: Rejection | B18: Danielle Generao | C18: KY | D18: RD | E18: P | F18: 40 | G18: 11 | H18: P | I18: 83 | J18: RD | K18: =SUM(D18:J18) -> 134 | L18: =SUMIF(D18:J18,"450") -> 0 | M18: =SUM(K18:L18) -> 134 | N18: =450*5 -> 2250 | O18: =N18-M18 -> 2116 | P18: =O18/N18*100% -> 0.94044444 | T18: Bea Mercado | U18: 1
A19: Rejection | B19: Edmark Bania | C19: Multi | D19: P | E19: 2 | F19: P | G19: RD | H19: RD | I19: 450 | J19: 450 | K19: =E19 -> 2 | L19: =SUMIF(D19:J19,"450") -> 900 | M19: =SUM(K19:L19) -> 902 | N19: =450*5 -> 2250 | O19: =N19-M19 -> 1348 | P19: =O19/N19*100% -> 0.59911111 | T19: Charlene Valdez | U19: 1
A20: Billing | B20: Eldrick Loreno | C20: NY | D20: RD | E20: P | F20: P | G20: P | H20: P | I20: 450 | J20: RD | L20: =SUMIF(D20:J20,"450") -> 450 | M20: =SUM(K20:L20) -> 450 | N20: =450*5 -> 2250 | O20: =N20-M20 -> 1800 | P20: =O20/N20*100% -> 0.8 | T20: Charyselle Cadelina | U20: 0.99377778
A21: Rebill | B21: Erika Ramos | C21: Multi | D21: RD | E21: P | F21: P | G21: P | H21: P | I21: P | J21: RD | K21: =SUM(E21:I21) -> 0 | L21: =SUMIF(D21:J21,"450") -> 0 | M21: =SUM(K21:L21) -> 0 | N21: =450*5 -> 2250 | O21: =N21-M21 -> 2250 | P21: =O21/N21*100% -> 1 | T21: Danielle Generao | U21: 0.94044444
A22: Billing | B22: Ethel Gregorio | C22: MA | D22: RD | E22: 17 | F22: 18 | G22: 2 | H22: 3 | I22: 11 | J22: RD | K22: =SUM(D22:I22) -> 51 | L22: =SUMIF(D22:J22,"450") -> 0 | M22: =SUM(K22:L22) -> 51 | N22: =450*5 -> 2250 | O22: =N22-M22 -> 2199 | P22: =O22/N22*100% -> 0.97733333 | T22: Edmark Bania | U22: 0.59911111
A23: Billing | B23: Eunice Bargo | C23: MA | D23: RD | E23: 1 | F23: 14 | G23: P | H23: P | I23: P | J23: RD | K23: =SUM(D23:I23) -> 15 | L23: =SUMIF(D23:J23,"450") -> 0 | M23: =SUM(K23:L23) -> 15 | N23: =450*5 -> 2250 | O23: =N23-M23 -> 2235 | P23: =O23/N23*100% -> 0.99333333 | T23: Eunice Padadnan | U23: 1
A24: Rejection | B24: Eunice Padadnan | C24: NY | D24: RD | E24: P | F24: P | G24: P | H24: P | I24: P | J24: RD | K24: =SUM(D24:J24) -> 0 | L24: =SUMIF(D24:J24,"450") -> 0 | M24: =SUM(K24:L24) -> 0 | N24: =450*5 -> 2250 | O24: =N24-M24 -> 2250 | P24: =O24/N24*100% -> 1 | T24: Francis Alba | U24: 1
A25: Billing | B25: Femie DC Domenden | C25: IL | D25: RD | E25: 9 | F25: P | G25: P | H25: P | I25: P | J25: RD | K25: =SUM(D25:J25) -> 9 | L25: =SUMIF(D25:J25,"450") -> 0 | M25: =SUM(K25:L25) -> 9 | N25: =450*5 -> 2250 | O25: =N25-M25 -> 2241 | P25: =O25/N25*100% -> 0.996 | T25: Glessie DeJesus | U25: 1
A26: Rejection | B26: Francis Alba | C26: Multi | D26: RD | E26: P | F26: P | G26: P | H26: P | I26: VL | J26: RD | K26: =SUM(D26:J26) -> 0 | L26: =SUMIF(D26:J26,"450") -> 0 | M26: =SUM(K26:L26) -> 0 | N26: =450*5 -> 2250 | O26: =N26-M26 -> 2250 | P26: =O26/N26*100% -> 1 | Q26: 1 | T26: Hanna Arceo | U26: 0.93466667
A27: Billing | B27: Francis Narboneta | C27: IL | D27: RD | E27: P | F27: 232 | G27: 450 | H27: 240 | I27: P | J27: RD | K27: =F27+H27 -> 472 | L27: =SUMIF(D27:J27,"450") -> 450 | M27: =SUM(K27:L27) -> 922 | N27: =450*5 -> 2250 | O27: =N27-M27 -> 1328 | P27: =O27/N27*100% -> 0.59022222 | T27: Iris Dahnielle Andalleon | U27: 1
A28: Billing | B28: Gladys Astilla | C28: MA | D28: RD | E28: 8 | F28: P | G28: P | H28: P | I28: VL | J28: RD | K28: =SUM(D28:I28) -> 8 | L28: =SUMIF(D28:J28,"450") -> 0 | M28: =SUM(K28:L28) -> 8 | N28: =450*4 -> 1800 | O28: =N28-M28 -> 1792 | P28: =O28/N28*100% -> 0.99555556 | Q28: 1 | T28: Jean Tan | U28: 1
A29: Rejection | B29: Glessie DeJesus | C29: KY | D29: RD | E29: P | F29: P | G29: P | H29: P | I29: P | J29: RD | K29: =SUM(D29:J29) -> 0 | L29: =SUMIF(D29:J29,"450") -> 0 | M29: =SUM(K29:L29) -> 0 | N29: =450*5 -> 2250 | O29: =N29-M29 -> 2250 | P29: =O29/N29*100% -> 1 | T29: Jeannie Bajaro | U29: 1
